Workbook

Sheet CTZ
B1: =B14 -> 45992 | C1: =C14 -> 46023 | D1: =D14 -> 46054 | E1: =E14 -> 46082 | F1: =F14 -> 46113 | G1: =G14 -> 46143 | H1: =H14 -> 46174 | I1: =I14 -> 46204 | ... CH1: =CH14 -> 48549
A2: Taux court (3m) | B2: =INDEX(Sc_eco!$B:$B, MATCH(B$14, Sc_eco!$A:$A, 0)) -> 0.02026 | C2: =INDEX(Sc_eco!$B:$B, MATCH(C$14, Sc_eco!$A:$A, 0)) -> 0.02031 | D2: =INDEX(Sc_eco!$B:$B, MATCH(D$14, Sc_eco!$A:$A, 0)) -> 0.02013 | E2: =INDEX(Sc_eco!$B:$B, MATCH(E$14, Sc_eco!$A:$A, 0)) -> 0.02079 | F2: =INDEX(Sc_eco!$B:$B, MATCH(F$14, Sc_eco!$A:$A, 0)) -> 0.021536 | G2: =INDEX(Sc_eco!$B:$B, MATCH(G$14, Sc_eco!$A:$A, 0)) -> 0.022281 | H2: =INDEX(Sc_eco!$B:$B, MATCH(H$14, Sc_eco!$A:$A, 0)) -> 0.023027 | I2: =INDEX(Sc_eco!$B:$B, MATCH(I$14, Sc_eco!$A:$A, 0)) -> 0.023772 | ... CH2: =INDEX(Sc_eco!$B:$B, MATCH(CH$14, Sc_eco!$A:$A, 0)) -> 0.02
A3: evol taux court | C3: =C2-B2 -> 5e-05 | D3: =D2-C2 -> -0.00018 | E3: =E2-D2 -> 0.00066 | F3: =F2-E2 -> 0.000746 | G3: =G2-F2 -> 0.000745 | H3: =H2-G2 -> 0.000746 | I3: =I2-H2 -> 0.000745 | J3: =J2-I2 -> 0.000746 | ... CH3: =CH2-CG2 -> 0
A4: Taux long (swap 10) | B4: =INDEX(Sc_eco!$C:$C, MATCH(B$14, Sc_eco!$A:$A, 0)) -> 0.02826 | C4: =INDEX(Sc_eco!$C:$C, MATCH(C$14, Sc_eco!$A:$A, 0)) -> 0.02762 | D4: =INDEX(Sc_eco!$C:$C, MATCH(D$14, Sc_eco!$A:$A, 0)) -> 0.02567 | E4: =INDEX(Sc_eco!$C:$C, MATCH(E$14, Sc_eco!$A:$A, 0)) -> 0.02962 | F4: =INDEX(Sc_eco!$C:$C, MATCH(F$14, Sc_eco!$A:$A, 0)) -> 0.02974 | G4: =INDEX(Sc_eco!$C:$C, MATCH(G$14, Sc_eco!$A:$A, 0)) -> 0.02986 | H4: =INDEX(Sc_eco!$C:$C, MATCH(H$14, Sc_eco!$A:$A, 0)) -> 0.02998 | I4: =INDEX(Sc_eco!$C:$C, MATCH(I$14, Sc_eco!$A:$A, 0)) -> 0.0301 | ... CH4: =INDEX(Sc_eco!$C:$C, MATCH(CH$14, Sc_eco!$A:$A, 0)) -> 0.0282
A5: evol swap 10 | C5: =C4-B4 -> -0.00064 | D5: =D4-C4 -> -0.00195 | E5: =E4-D4 -> 0.00395 | F5: =F4-E4 -> 0.00012 | G5: =G4-F4 -> 0.00012 | H5: =H4-G4 -> 0.00012 | I5: =I4-H4 -> 0.00012 | J5: =J4-I4 -> 0.00012 | ... CH5: =CH4-CG4 -> 0
A6: Spread A | B6: =INDEX(Sc_eco!$H:$H, MATCH(B$14, Sc_eco!$A:$A, 0)) -> 0.0068 | C6: =INDEX(Sc_eco!$H:$H, MATCH(C$14, Sc_eco!$A:$A, 0)) -> 0.0068 | D6: =INDEX(Sc_eco!$H:$H, MATCH(D$14, Sc_eco!$A:$A, 0)) -> 0.0068 | E6: =INDEX(Sc_eco!$H:$H, MATCH(E$14, Sc_eco!$A:$A, 0)) -> 0.0068 | F6: =INDEX(Sc_eco!$H:$H, MATCH(F$14, Sc_eco!$A:$A, 0)) -> 0.0068 | G6: =INDEX(Sc_eco!$H:$H, MATCH(G$14, Sc_eco!$A:$A, 0)) -> 0.0068 | H6: =INDEX(Sc_eco!$H:$H, MATCH(H$14, Sc_eco!$A:$A, 0)) -> 0.0068 | I6: =INDEX(Sc_eco!$H:$H, MATCH(I$14, Sc_eco!$A:$A, 0)) -> 0.0068 | ... CH6: =INDEX(Sc_eco!$H:$H, MATCH(CH$14, Sc_eco!$A:$A, 0)) -> 0.0068
A7: TEC 10 | B7: =B4+B6 -> 0.03506 | C7: =C4+C6 -> 0.03442 | D7: =D4+D6 -> 0.03247 | E7: =E4+E6 -> 0.03642 | F7: =F4+F6 -> 0.03654 | G7: =G4+G6 -> 0.03666 | H7: =H4+H6 -> 0.03678 | I7: =I4+I6 -> 0.0369 | ... CH7: =CH4+CH6 -> 0.035
A9: Check taux court | B9: =B2-B17 -> -0.00019337624 | C9: =C2-C17 -> 0 | D9: =D2-D17 -> 9.7144515e-17 | E9: =E2-E17 -> 0 | F9: =F2-F17 -> -2.0122792e-16 | G9: =G2-G17 -> -2.0122792e-16 | H9: =H2-H17 -> 3.989864e-16 | I9: =I2-I17 -> -9.7144515e-17 | ... CH9: =CH2-CH17 -> -0.00045337624
A10: check swap 10 - TZC 10 | B10: =B4-B134 -> -0.00037000011 | C10: =C4-C134 -> -0.00035641312 | D10: =D4-D134 -> -0.00024987166 | E10: =E4-E134 -> -0.00046373659 | F10: =F4-F134 -> -0.00043229345 | G10: =G4-G134 -> -0.00040068293 | H10: =H4-H134 -> -0.00036879883 | I10: =I4-I134 -> -0.00033674864 | ... CH10: =CH4-CH134 -> -0.00043000011
B12: =YEAR(B14) -> 2025 | C12: =YEAR(C14) -> 2026 | D12: =YEAR(D14) -> 2026 | E12: =YEAR(E14) -> 2026 | F12: =YEAR(F14) -> 2026 | G12: =YEAR(G14) -> 2026 | H12: =YEAR(H14) -> 2026 | I12: =YEAR(I14) -> 2026 | ... CH12: =YEAR(CH14) -> 2032
A14: CTZ sans VA | B14: 45992 | C14: 46023 | D14: 46054 | E14: 46082 | F14: 46113 | G14: 46143 | H14: 46174 | I14: 46204 | J14: 46235 | K14: 46266 | L14: 46296 | M14: 46327 | N14: 46357 | O14: 46388 | P14: 46419 | Q14: 46447 | R14: 46478 | S14: 46508 | T14: 46539 | U14: 46569 | V14: 46600 | W14: 46631 | X14: 46661 | Y14: 46692 | Z14: 46722 | AA14: 46753 | AB14: 46784 | AC14: 46813 | AD14: 46844 | AE14: 46874 | AF14: 46905 | AG14: 46935 | AH14: 46966 | AI14: 46997 | AJ14: 47027 | AK14: 47058 | AL14: 47088 | AM14: 47119 | AN14: 47150 | AO14: 47178 | AP14: 47209 | AQ14: 47239 | AR14: 47270 | AS14: 47300 | AT14: 47331 | AU14: 47362 | AV14: 47392 | AW14: 47423 | AX14: 47453 | AY14: 47484 | AZ14: 47515 | BA14: 47543 | BB14: 47574 | BC14: 47604 | BD14: 47635 | BE14: 47665 | BF14: 47696 | BG14: 47727 | BH14: 47757 | BI14: 47788 | BJ14: 47818 | BK14: 47849 | BL14: 47880 | BM14: 47908 | BN14: 47939 | BO14: 47969 | BP14: 48000 | BQ14: 48030 | BR14: 48061 | BS14: 48092 | BT14: 48122 | BU14: 48153 | BV14: 48183 | BW14: 48214 | BX14: 48245 | BY14: 48274 | BZ14: 48305 | CA14: 48335 | CB14: 48366 | CC14: 48396 | CD14: 48427 | CE14: 48458 | CF14: 48488 | CG14: 48519 | CH14: 48549
A15: 1e mois | B15: ='CTZ 311225'!C8 -> 0.02042571 | C15: ='solvencii lab'!C3 -> 0.020230743 | D15: ='solvencii lab'!D3 -> 0.02007805 | E15: ='solvencii lab'!E3 -> 0.020687843 | F15: ='solvencii lab'!F3 -> 0.021444527 | G15: ='solvencii lab'!G3 -> 0.022200114 | H15: ='solvencii lab'!H3 -> 0.022956638 | I15: ='solvencii lab'!I3 -> 0.023712065 | J15: ='solvencii lab'!J3 -> 0.024468429 | ... AK15: ='solvencii lab'!AK3 -> 0.020330546 | AL15: =B15 -> 0.02042571 | AM15: =$AL15 -> 0.02042571 | AN15: =$AL15 -> 0.02042571 | AO15: =$AL15 -> 0.02042571 | AP15: =$AL15 -> 0.02042571 | AQ15: =$AL15 -> 0.02042571 | AR15: =$AL15 -> 0.02042571 | AS15: =$AL15 -> 0.02042571 | AT15: =$AL15 -> 0.02042571 | ... CH15: =$AL15 -> 0.02042571
A16: 2e mois | B16: ='CTZ 311225'!C9 -> 0.020437686 | C16: ='solvencii lab'!C4 -> 0.020262135 | D16: ='solvencii lab'!D4 -> 0.020099231 | E16: ='solvencii lab'!E4 -> 0.020727714 | F16: ='solvencii lab'!F4 -> 0.021480204 | G16: ='solvencii lab'!G4 -> 0.022231646 | H16: ='solvencii lab'!H4 -> 0.02298406 | I16: ='solvencii lab'!I4 -> 0.023735426 | J16: ='solvencii lab'!J4 -> 0.024487764 | ... AK16: ='solvencii lab'!AK4 -> 0.020364614 | AL16: =B16 -> 0.020437686 | AM16: =$AL16 -> 0.020437686 | AN16: =$AL16 -> 0.020437686 | AO16: =$AL16 -> 0.020437686 | AP16: =$AL16 -> 0.020437686 | AQ16: =$AL16 -> 0.020437686 | AR16: =$AL16 -> 0.020437686 | AS16: =$AL16 -> 0.020437686 | AT16: =$AL16 -> 0.020437686 | ... CH16: =$AL16 -> 0.020437686
A17: 3e mois | B17: ='CTZ 311225'!C10 -> 0.020453376 | C17: ='solvencii lab'!C5 -> 0.02031 | D17: ='solvencii lab'!D5 -> 0.02013 | E17: ='solvencii lab'!E5 -> 0.02079 | F17: ='solvencii lab'!F5 -> 0.021536 | G17: ='solvencii lab'!G5 -> 0.022281 | H17: ='solvencii lab'!H5 -> 0.023027 | I17: ='solvencii lab'!I5 -> 0.023772 | J17: ='solvencii lab'!J5 -> 0.024518 | ... AK17: ='solvencii lab'!AK5 -> 0.020417 | AL17: =B17 -> 0.020453376 | AM17: =$AL17 -> 0.020453376 | AN17: =$AL17 -> 0.020453376 | AO17: =$AL17 -> 0.020453376 | AP17: =$AL17 -> 0.020453376 | AQ17: =$AL17 -> 0.020453376 | AR17: =$AL17 -> 0.020453376 | AS17: =$AL17 -> 0.020453376 | AT17: =$AL17 -> 0.020453376 | ... CH17: =$AL17 -> 0.020453376
A18: 4e mois | B18: ='CTZ 311225'!C11 -> 0.020472769 | C18: ='solvencii lab'!C6 -> 0.0203722 | D18: ='solvencii lab'!D6 -> 0.020169131 | E18: ='solvencii lab'!E6 -> 0.020871777 | F18: ='solvencii lab'!F6 -> 0.0216093 | G18: ='solvencii lab'!G6 -> 0.022345869 | H18: ='solvencii lab'!H6 -> 0.023083459 | I18: ='solvencii lab'!I6 -> 0.023820096 | J18: ='solvencii lab'!J6 -> 0.024557753 | ... AK18: ='solvencii lab'!AK6 -> 0.020485322 | AL18: =B18 -> 0.020472769 | AM18: =$AL18 -> 0.020472769 | AN18: =$AL18 -> 0.020472769 | AO18: =$AL18 -> 0.020472769 | AP18: =$AL18 -> 0.020472769 | AQ18: =$AL18 -> 0.020472769 | AR18: =$AL18 -> 0.020472769 | AS18: =$AL18 -> 0.020472769 | AT18: =$AL18 -> 0.020472769 | ... CH18: =$AL18 -> 0.020472769
A19: 5e mois | B19: ='CTZ 311225'!C12 -> 0.020495854 | C19: ='solvencii lab'!C7 -> 0.020441589 | D19: ='solvencii lab'!D7 -> 0.020212533 | E19: ='solvencii lab'!E7 -> 0.020963266 | F19: ='solvencii lab'!F7 -> 0.021691346 | G19: ='solvencii lab'!G7 -> 0.022418519 | H19: ='solvencii lab'!H7 -> 0.023146728 | I19: ='solvencii lab'!I7 -> 0.02387403 | J19: ='solvencii lab'!J7 -> 0.024602367 | ... AK19: ='solvencii lab'!AK7 -> 0.020561616 | AL19: =B19 -> 0.020495854 | AM19: =$AL19 -> 0.020495854 | AN19: =$AL19 -> 0.020495854 | AO19: =$AL19 -> 0.020495854 | AP19: =$AL19 -> 0.020495854 | AQ19: =$AL19 -> 0.020495854 | AR19: =$AL19 -> 0.020495854 | AS19: =$AL19 -> 0.020495854 | AT19: =$AL19 -> 0.020495854 | ... CH19: =$AL19 -> 0.020495854
A20: 6e mois | B20: ='CTZ 311225'!C13 -> 0.02052262 | C20: ='solvencii lab'!C8 -> 0.020514391 | D20: ='solvencii lab'!D8 -> 0.020258046 | E20: ='solvencii lab'!E8 -> 0.021059298 | F20: ='solvencii lab'!F8 -> 0.021777512 | G20: ='solvencii lab'!G8 -> 0.022494863 | H20: ='solvencii lab'!H8 -> 0.023213262 | I20: ='solvencii lab'!I8 -> 0.023930797 | J20: ='solvencii lab'!J8 -> 0.02464938 | ... AK20: ='solvencii lab'!AK8 -> 0.020641673 | AL20: =B20 -> 0.02052262 | AM20: =$AL20 -> 0.02052262 | AN20: =$AL20 -> 0.02052262 | AO20: =$AL20 -> 0.02052262 | AP20: =$AL20 -> 0.02052262 | AQ20: =$AL20 -> 0.02052262 | AR20: =$AL20 -> 0.02052262 | AS20: =$AL20 -> 0.02052262 | AT20: =$AL20 -> 0.02052262 | ... CH20: =$AL20 -> 0.02052262
A21: 7e mois | B21: ='CTZ 311225'!C14 -> 0.020553059 | C21: ='solvencii lab'!C9 -> 0.020588989 | D21: ='solvencii lab'!D9 -> 0.020304744 | E21: ='solvencii lab'!E9 -> 0.02115766 | F21: ='solvencii lab'!F9 -> 0.021865817 | G21: ='solvencii lab'!G9 -> 0.022573151 | H21: ='solvencii lab'!H9 -> 0.023281542 | I21: ='solvencii lab'!I9 -> 0.023989112 | J21: ='solvencii lab'!J9 -> 0.024697739 | ... AK21: ='solvencii lab'!AK9 -> 0.020723691 | AL21: =B21 -> 0.020553059 | AM21: =$AL21 -> 0.020553059 | AN21: =$AL21 -> 0.020553059 | AO21: =$AL21 -> 0.020553059 | AP21: =$AL21 -> 0.020553059 | AQ21: =$AL21 -> 0.020553059 | AR21: =$AL21 -> 0.020553059 | AS21: =$AL21 -> 0.020553059 | AT21: =$AL21 -> 0.020553059 | ... CH21: =$AL21 -> 0.020553059
A22: 8e mois | B22: ='CTZ 311225'!C15 -> 0.020587159 | C22: ='solvencii lab'!C10 -> 0.020664577 | D22: ='solvencii lab'!D10 -> 0.020352164 | E22: ='solvencii lab'!E10 -> 0.02125725 | F22: ='solvencii lab'!F10 -> 0.021955271 | G22: ='solvencii lab'!G10 -> 0.022652509 | H22: ='solvencii lab'!H10 -> 0.023350812 | I22: ='solvencii lab'!I10 -> 0.024048331 | J22: ='solvencii lab'!J10 -> 0.024746916 | ... AK22: ='solvencii lab'!AK10 -> 0.020806772 | AL22: =B22 -> 0.020587159 | AM22: =$AL22 -> 0.020587159 | AN22: =$AL22 -> 0.020587159 | AO22: =$AL22 -> 0.020587159 | AP22: =$AL22 -> 0.020587159 | AQ22: =$AL22 -> 0.020587159 | AR22: =$AL22 -> 0.020587159 | AS22: =$AL22 -> 0.020587159 | AT22: =$AL22 -> 0.020587159 | ... CH22: =$AL22 -> 0.020587159
A23: 9e mois | B23: ='CTZ 311225'!C16 -> 0.020624913 | C23: ='solvencii lab'!C11 -> 0.020740708 | D23: ='solvencii lab'!D11 -> 0.02040005 | E23: ='solvencii lab'!E11 -> 0.021357458 | F23: ='solvencii lab'!F11 -> 0.022045329 | G23: ='solvencii lab'!G11 -> 0.022732455 | H23: ='solvencii lab'!H11 -> 0.02342065 | I23: ='solvencii lab'!I11 -> 0.0241081 | J23: ='solvencii lab'!J11 -> 0.024796621 | ... AK23: ='solvencii lab'!AK11 -> 0.020890419 | AL23: =B23 -> 0.020624913 | AM23: =$AL23 -> 0.020624913 | AN23: =$AL23 -> 0.020624913 | AO23: =$AL23 -> 0.020624913 | AP23: =$AL23 -> 0.020624913 | AQ23: =$AL23 -> 0.020624913 | AR23: =$AL23 -> 0.020624913 | AS23: =$AL23 -> 0.020624913 | AT23: =$AL23 -> 0.020624913 | ... CH23: =$AL23 -> 0.020624913
A24: 10e mois | B24: ='CTZ 311225'!C17 -> 0.02066631 | C24: ='solvencii lab'!C12 -> 0.020817117 | D24: ='solvencii lab'!D12 -> 0.020448249 | E24: ='solvencii lab'!E12 -> 0.02145792 | F24: ='solvencii lab'!F12 -> 0.022135665 | G24: ='solvencii lab'!G12 -> 0.0228127 | H24: ='solvencii lab'!H12 -> 0.023490808 | I24: ='solvencii lab'!I12 -> 0.024168205 | J24: ='solvencii lab'!J12 -> 0.024846678 | ... AK24: ='solvencii lab'!AK12 -> 0.020974334 | AL24: =B24 -> 0.02066631 | AM24: =$AL24 -> 0.02066631 | AN24: =$AL24 -> 0.02066631 | AO24: =$AL24 -> 0.02066631 | AP24: =$AL24 -> 0.02066631 | AQ24: =$AL24 -> 0.02066631 | AR24: =$AL24 -> 0.02066631 | AS24: =$AL24 -> 0.02066631 | AT24: =$AL24 -> 0.02066631 | ... CH24: =$AL24 -> 0.02066631
A25: 11e mois | B25: ='CTZ 311225'!C18 -> 0.020711342 | C25: ='solvencii lab'!C13 -> 0.020893635 | D25: ='solvencii lab'!D13 -> 0.020496665 | E25: ='solvencii lab'!E13 -> 0.021558406 | F25: ='solvencii lab'!F13 -> 0.022226072 | G25: ='solvencii lab'!G13 -> 0.022893061 | H25: ='solvencii lab'!H13 -> 0.023561126 | I25: ='solvencii lab'!I13 -> 0.024228513 | J25: ='solvencii lab'!J13 -> 0.024896978 | ... AK25: ='solvencii lab'!AK13 -> 0.021058331 | AL25: =B25 -> 0.020711342 | AM25: =$AL25 -> 0.020711342 | AN25: =$AL25 -> 0.020711342 | AO25: =$AL25 -> 0.020711342 | AP25: =$AL25 -> 0.020711342 | AQ25: =$AL25 -> 0.020711342 | AR25: =$AL25 -> 0.020711342 | AS25: =$AL25 -> 0.020711342 | AT25: =$AL25 -> 0.020711342 | ... CH25: =$AL25 -> 0.020711342
A26: 12e mois | B26: ='CTZ 311225'!C19 -> 0.02076 | C26: ='solvencii lab'!C14 -> 0.020970151 | D26: ='solvencii lab'!D14 -> 0.020545233 | E26: ='solvencii lab'!E14 -> 0.021658766 | F26: ='solvencii lab'!F14 -> 0.022316415 | G26: ='solvencii lab'!G14 -> 0.02297342 | H26: ='solvencii lab'!H14 -> 0.0236315 | I26: ='solvencii lab'!I14 -> 0.024288935 | J26: ='solvencii lab'!J14 -> 0.024947447 | ... AK26: ='solvencii lab'!AK14 -> 0.021142287 | AL26: =B26 -> 0.02076 | AM26: =$AL26 -> 0.02076 | AN26: =$AL26 -> 0.02076 | AO26: =$AL26 -> 0.02076 | AP26: =$AL26 -> 0.02076 | AQ26: =$AL26 -> 0.02076 | AR26: =$AL26 -> 0.02076 | AS26: =$AL26 -> 0.02076 | AT26: =$AL26 -> 0.02076 | ... CH26: =$AL26 -> 0.02076
... A614: 600e mois | B614: ='CTZ 311225'!C607 -> 0.03302814 | C614: ='solvencii lab'!C602 -> 0.033414934 | D614: ='solvencii lab'!D602 -> 0.032344849 | E614: ='solvencii lab'!E602 -> 0.034528883 | F614: ='solvencii lab'!F602 -> 0.034606117 | G614: ='solvencii lab'!G602 -> 0.034683464 | H614: ='solvencii lab'!H602 -> 0.034760951 | I614: ='solvencii lab'!I602 -> 0.034838553 | J614: ='solvencii lab'!J602 -> 0.034916298 | ... AK614: ='solvencii lab'!AK602 -> 0.033736203 | AL614: =B614 -> 0.03302814 | AM614: =$AL614 -> 0.03302814 | AN614: =$AL614 -> 0.03302814 | AO614: =$AL614 -> 0.03302814 | AP614: =$AL614 -> 0.03302814 | AQ614: =$AL614 -> 0.03302814 | AR614: =$AL614 -> 0.03302814 | AS614: =$AL614 -> 0.03302814 | AT614: =$AL614 -> 0.03302814 | ... CH614: =$AL614 -> 0.03302814

Sheet CTZ input
A3: evol 3 mois | C3: =CTZ!C3 -> 5e-05 | D3: =CTZ!D3 -> -0.00018 | E3: =CTZ!E3 -> 0.00066 | F3: =CTZ!F3 -> 0.000746 | G3: =CTZ!G3 -> 0.000745 | H3: =CTZ!H3 -> 0.000746 | I3: =CTZ!I3 -> 0.000745 | J3: =CTZ!J3 -> 0.000746 | ... CH3: =CTZ!CH3 -> 0
A5: evol 10 ans | C5: =CTZ!C5 -> -0.00064 | D5: =CTZ!D5 -> -0.00195 | E5: =CTZ!E5 -> 0.00395 | F5: =CTZ!F5 -> 0.00012 | G5: =CTZ!G5 -> 0.00012 | H5: =CTZ!H5 -> 0.00012 | I5: =CTZ!I5 -> 0.00012 | J5: =CTZ!J5 -> 0.00012 | ... CH5: =CTZ!CH5 -> 0
C6: =AVERAGE(C3, C5) -> -0.000295 | D6: =AVERAGE(D3, D5) -> -0.001065 | E6: =AVERAGE(E3, E5) -> 0.002305 | F6: =AVERAGE(F3, F5) -> 0.000433 | G6: =AVERAGE(G3, G5) -> 0.0004325 | H6: =AVERAGE(H3, H5) -> 0.000433 | I6: =AVERAGE(I3, I5) -> 0.0004325 | J6: =AVERAGE(J3, J5) -> 0.000433 | ... CH6: =AVERAGE(CH3, CH5) -> 0
B14: =CTZ!B1 -> 45992 | C14: =CTZ!C1 -> 46023 | D14: =CTZ!D1 -> 46054 | E14: =CTZ!E1 -> 46082 | F14: =CTZ!F1 -> 46113 | G14: =CTZ!G1 -> 46143 | H14: =CTZ!H1 -> 46174 | I14: =CTZ!I1 -> 46204 | ... CH14: =CTZ!CH1 -> 48549
A15: =CTZ!A15 -> 1e mois | B15: =CTZ!B15 -> 0.02042571 | C15: =B15+C3 -> 0.02047571 | D15: =C15+D3 -> 0.02029571 | E15: =D15+E3 -> 0.02095571 | F15: =E15+F3 -> 0.02170171 | G15: =F15+G3 -> 0.02244671 | H15: =G15+H3 -> 0.02319271 | I15: =H15+I3 -> 0.02393771 | J15: =I15+J3 -> 0.02468371 | ... CH15: =CG15+CH3 -> 0.02016571
A16: =CTZ!A16 -> 2e mois | B16: =CTZ!B16 -> 0.020437686 | C16: =B16+C3 -> 0.020487686 | D16: =C16+D3 -> 0.020307686 | E16: =D16+E3 -> 0.020967686 | F16: =E16+F3 -> 0.021713686 | G16: =F16+G3 -> 0.022458686 | H16: =G16+H3 -> 0.023204686 | I16: =H16+I3 -> 0.023949686 | J16: =I16+J3 -> 0.024695686 | ... CH16: =CG16+CH3 -> 0.020177686
A17: =CTZ!A17 -> 3e mois | B17: =CTZ!B17 -> 0.020453376 | C17: =B17+C3 -> 0.020503376 | D17: =C17+D3 -> 0.020323376 | E17: =D17+E3 -> 0.020983376 | F17: =E17+F3 -> 0.021729376 | G17: =F17+G3 -> 0.022474376 | H17: =G17+H3 -> 0.023220376 | I17: =H17+I3 -> 0.023965376 | J17: =I17+J3 -> 0.024711376 | ... CH17: =CG17+CH3 -> 0.020193376
A18: =CTZ!A18 -> 4e mois | B18: =CTZ!B18 -> 0.020472769
A19: =CTZ!A19 -> 5e mois | B19: =CTZ!B19 -> 0.020495854
A20: =CTZ!A20 -> 6e mois | B20: =CTZ!B20 -> 0.02052262
A21: =CTZ!A21 -> 7e mois | B21: =CTZ!B21 -> 0.020553059
A22: =CTZ!A22 -> 8e mois | B22: =CTZ!B22 -> 0.020587159
A23: =CTZ!A23 -> 9e mois | B23: =CTZ!B23 -> 0.020624913
A24: =CTZ!A24 -> 10e mois | B24: =CTZ!B24 -> 0.02066631
A25: =CTZ!A25 -> 11e mois | B25: =CTZ!B25 -> 0.020711342
A26: =CTZ!A26 -> 12e mois | B26: =CTZ!B26 -> 0.02076
A27: =CTZ!A27 -> 13e mois | B27: =CTZ!B27 -> 0.020812283
A28: =CTZ!A28 -> 14e mois | B28: =CTZ!B28 -> 0.020868211
A29: =CTZ!A29 -> 15e mois | B29: =CTZ!B29 -> 0.020927801
... A73: =CTZ!A73 -> 59e mois | B73: =CTZ!B73 -> 0.024716327
A74: =CTZ!A74 -> 60e mois | B74: =CTZ!B74 -> 0.02479 | C74: =B74+C$5 -> 0.02415 | D74: =C74+D$5 -> 0.0222 | E74: =D74+E$5 -> 0.02615 | F74: =E74+F$5 -> 0.02627 | G74: =F74+G$5 -> 0.02639 | H74: =G74+H$5 -> 0.02651 | I74: =H74+I$5 -> 0.02663 | J74: =I74+J$5 -> 0.02675 | ... CH74: =CG74+CH$5 -> 0.02473
A75: =CTZ!A75 -> 61e mois | B75: =CTZ!B75 -> 0.024862889
A76: =CTZ!A76 -> 62e mois | B76: =CTZ!B76 -> 0.024935122
A77: =CTZ!A77 -> 63e mois | B77: =CTZ!B77 -> 0.025006847
A78: =CTZ!A78 -> 64e mois | B78: =CTZ!B78 -> 0.025078204
A79: =CTZ!A79 -> 65e mois | B79: =CTZ!B79 -> 0.025149323
A80: =CTZ!A80 -> 66e mois | B80: =CTZ!B80 -> 0.025220328
A81: =CTZ!A81 -> 67e mois | B81: =CTZ!B81 -> 0.025291335
A82: =CTZ!A82 -> 68e mois | B82: =CTZ!B82 -> 0.025362452
A83: =CTZ!A83 -> 69e mois | B83: =CTZ!B83 -> 0.025433783
A84: =CTZ!A84 -> 70e mois | B84: =CTZ!B84 -> 0.025505424
A85: =CTZ!A85 -> 71e mois | B85: =CTZ!B85 -> 0.025577467
A86: =CTZ!A86 -> 72e mois | B86: =CTZ!B86 -> 0.02565 | C86: =B86+C$5 -> 0.02501 | D86: =C86+D$5 -> 0.02306 | E86: =D86+E$5 -> 0.02701 | F86: =E86+F$5 -> 0.02713 | G86: =F86+G$5 -> 0.02725 | H86: =G86+H$5 -> 0.02737 | I86: =H86+I$5 -> 0.02749 | J86: =I86+J$5 -> 0.02761 | ... CH86: =CG86+CH$5 -> 0.02559
A87: =CTZ!A87 -> 73e mois | B87: =CTZ!B87 -> 0.025723055
A88: =CTZ!A88 -> 74e mois | B88: =CTZ!B88 -> 0.025796466
A89: =CTZ!A89 -> 75e mois | B89: =CTZ!B89 -> 0.025870028
A90: =CTZ!A90 -> 76e mois | B90: =CTZ!B90 -> 0.025943547
A91: =CTZ!A91 -> 77e mois | B91: =CTZ!B91 -> 0.026016841
A92: =CTZ!A92 -> 78e mois | B92: =CTZ!B92 -> 0.026089734
A93: =CTZ!A93 -> 79e mois | B93: =CTZ!B93 -> 0.026162062
...

Sheet Sc_eco
B1: swap_0.25 | C1: swap_10 | D1: swap_15 | E1: Risq,souverain | F1: AAA | G1: AA | H1: A | I1: BBB | J1: BB | K1: B | L1: CCC | M1: CC | N1: C | O1: HY | P1: NR | Q1: BBB R332-20 | R1: BB R332-20 | S1: A R332-20 | T1: AA R332-20 | U1: D R332-20
A2: 45992 | B2: 0.02026 | C2: 0.02826 | D2: =C2+0.2% -> 0.03026 | E2: 0 | F2: 0 | G2: 0.00408 | H2: 0.0068 | I2: 0.00952 | J2: 0.01632 | K2: 0.02652 | L2: 0.0408 | M2: 0.0408 | N2: 0.0408 | O2: 0.0408 | P2: 0.0204 | Q2: 0.0136 | R2: 0.0408 | S2: 0.0408 | T2: 0.0408 | U2: 0.0408 | V2: =C2-B2 -> 0.008
A3: 46023 | B3: 0.02031 | C3: 0.02762 | D3: =C3+0.2% -> 0.02962 | E3: 0 | F3: 0 | G3: 0.00408 | H3: 0.0068 | I3: 0.00952 | J3: 0.01632 | K3: 0.02652 | L3: 0.0408 | M3: 0.0408 | N3: 0.0408 | O3: 0.0408 | P3: 0.0204 | Q3: 0.0136 | R3: 0.0408 | S3: 0.0408 | T3: 0.0408 | U3: 0.0408 | V3: =C3-B3 -> 0.00731
A4: 46054 | B4: 0.02013 | C4: 0.02567 | D4: =C4+0.2% -> 0.02767 | E4: 0 | F4: 0 | G4: 0.00408 | H4: 0.0068 | I4: 0.00952 | J4: 0.01632 | K4: 0.02652 | L4: 0.0408 | M4: 0.0408 | N4: 0.0408 | O4: 0.0408 | P4: 0.0204 | Q4: 0.0136 | R4: 0.0408 | S4: 0.0408 | T4: 0.0408 | U4: 0.0408 | V4: =C4-B4 -> 0.00554
A5: 46082 | B5: 0.02079 | C5: 0.02962 | D5: =C5+0.2% -> 0.03162 | E5: 0 | F5: 0 | G5: 0.00408 | H5: 0.0068 | I5: 0.00952 | J5: 0.01632 | K5: 0.02652 | L5: 0.0408 | M5: 0.0408 | N5: 0.0408 | O5: 0.0408 | P5: 0.0204 | Q5: 0.0136 | R5: 0.0408 | S5: 0.0408 | T5: 0.0408 | U5: 0.0408 | V5: =C5-B5 -> 0.00883
A6: 46113 | B6: 0.021536 | C6: 0.02974 | D6: =C6+0.2% -> 0.03174 | E6: 0 | F6: 0 | G6: 0.00408 | H6: 0.0068 | I6: 0.00952 | J6: 0.01632 | K6: 0.02652 | L6: 0.0408 | M6: 0.0408 | N6: 0.0408 | O6: 0.0408 | P6: 0.0204 | Q6: 0.0136 | R6: 0.0408 | S6: 0.0408 | T6: 0.0408 | U6: 0.0408 | V6: =C6-B6 -> 0.008204
A7: 46143 | B7: 0.022281 | C7: 0.02986 | D7: =C7+0.2% -> 0.03186 | E7: 0 | F7: 0 | G7: 0.00408 | H7: 0.0068 | I7: 0.00952 | J7: 0.01632 | K7: 0.02652 | L7: 0.0408 | M7: 0.0408 | N7: 0.0408 | O7: 0.0408 | P7: 0.0204 | Q7: 0.0136 | R7: 0.0408 | S7: 0.0408 | T7: 0.0408 | U7: 0.0408 | V7: =C7-B7 -> 0.007579
A8: 46174 | B8: 0.023027 | C8: 0.02998 | D8: =C8+0.2% -> 0.03198 | E8: 0 | F8: 0 | G8: 0.00408 | H8: 0.0068 | I8: 0.00952 | J8: 0.01632 | K8: 0.02652 | L8: 0.0408 | M8: 0.0408 | N8: 0.0408 | O8: 0.0408 | P8: 0.0204 | Q8: 0.0136 | R8: 0.0408 | S8: 0.0408 | T8: 0.0408 | U8: 0.0408 | V8: =C8-B8 -> 0.006953
A9: 46204 | B9: 0.023772 | C9: 0.0301 | D9: =C9+0.2% -> 0.0321 | E9: 0 | F9: 0 | G9: 0.00408 | H9: 0.0068 | I9: 0.00952 | J9: 0.01632 | K9: 0.02652 | L9: 0.0408 | M9: 0.0408 | N9: 0.0408 | O9: 0.0408 | P9: 0.0204 | Q9: 0.0136 | R9: 0.0408 | S9: 0.0408 | T9: 0.0408 | U9: 0.0408 | V9: =C9-B9 -> 0.006328
A10: 46235 | B10: 0.024518 | C10: 0.03022 | D10: =C10+0.2% -> 0.03222 | E10: 0 | F10: 0 | G10: 0.00408 | H10: 0.0068 | I10: 0.00952 | J10: 0.01632 | K10: 0.02652 | L10: 0.0408 | M10: 0.0408 | N10: 0.0408 | O10: 0.0408 | P10: 0.0204 | Q10: 0.0136 | R10: 0.0408 | S10: 0.0408 | T10: 0.0408 | U10: 0.0408 | V10: =C10-B10 -> 0.005702
A11: 46266 | B11: 0.025263 | C11: 0.03034 | D11: =C11+0.2% -> 0.03234 | E11: 0 | F11: 0 | G11: 0.00408 | H11: 0.0068 | I11: 0.00952 | J11: 0.01632 | K11: 0.02652 | L11: 0.0408 | M11: 0.0408 | N11: 0.0408 | O11: 0.0408 | P11: 0.0204 | Q11: 0.0136 | R11: 0.0408 | S11: 0.0408 | T11: 0.0408 | U11: 0.0408 | V11: =C11-B11 -> 0.005077
A12: 46296 | B12: 0.026009 | C12: 0.03046 | D12: =C12+0.2% -> 0.03246 | E12: 0 | F12: 0 | G12: 0.00408 | H12: 0.0068 | I12: 0.00952 | J12: 0.01632 | K12: 0.02652 | L12: 0.0408 | M12: 0.0408 | N12: 0.0408 | O12: 0.0408 | P12: 0.0204 | Q12: 0.0136 | R12: 0.0408 | S12: 0.0408 | T12: 0.0408 | U12: 0.0408 | V12: =C12-B12 -> 0.004451
A13: 46327 | B13: 0.026754 | C13: 0.03058 | D13: =C13+0.2% -> 0.03258 | E13: 0 | F13: 0 | G13: 0.00408 | H13: 0.0068 | I13: 0.00952 | J13: 0.01632 | K13: 0.02652 | L13: 0.0408 | M13: 0.0408 | N13: 0.0408 | O13: 0.0408 | P13: 0.0204 | Q13: 0.0136 | R13: 0.0408 | S13: 0.0408 | T13: 0.0408 | U13: 0.0408 | V13: =C13-B13 -> 0.003826
... A86: 48549 | B86: 0.02 | C86: 0.0282 | D86: =C86+0.2% -> 0.0302 | E86: 0 | F86: 0 | G86: 0.00408 | H86: 0.0068 | I86: 0.00952 | J86: 0.01632 | K86: 0.02652 | L86: 0.0408 | M86: 0.0408 | N86: 0.0408 | O86: 0.0408 | P86: 0.0204 | Q86: 0.0136 | R86: 0.0408 | S86: 0.0408 | T86: 0.0408 | U86: 0.0408 | V86: =C86-B86 -> 0.0082

Sheet CTZ 311225
A1: Coupon_freq | B1: 1
A2: LLP | B2: 20
A3: Convergence | B3: 40
A4: UFR | B4: 3.3
A5: alpha | B5: 0.073632
A6: CRA | B6: 10
B7: TZ avec VA | C7: TZ sans VA | D7: Taux fwd 1M | F7: CTZ Solvéo à partir du sc eco
A8: 46023 | B8: 0.021833872 | C8: 0.02042571 | D8: 0.021855395 | F8: 0.02026
A9: 46054 | B9: 0.021844634 | C9: 0.020437686 | D9: 0.021888334 | F9: 0.02015735
A10: 46082 | B10: 0.0218592 | C10: 0.020453376 | D10: 0.021932649 | F10: 0.02026
A11: 46113 | B11: 0.021877562 | C11: 0.020472769 | D11: 0.021988303 | F11: 0.020453229
A12: 46143 | B12: 0.021899709 | C12: 0.020495854 | D12: 0.022055262 | F12: 0.020679946
A13: 46174 | B13: 0.021925633 | C13: 0.02052262 | D13: 0.02213349 | F13: 0.020912845
A14: 46204 | B14: 0.021955324 | C14: 0.020553059 | D14: 0.022222955 | F14: 0.021139745
A15: 46235 | B15: 0.021988774 | C15: 0.020587159 | D15: 0.022323627 | F15: 0.021355956
A16: 46266 | B16: 0.022025975 | C16: 0.020624913 | D16: 0.022435477 | F16: 0.02156034
A17: 46296 | B17: 0.022066918 | C17: 0.02066631 | D17: 0.022558478 | F17: 0.021753332
A18: 46327 | B18: 0.022111595 | C18: 0.020711342 | D18: 0.022692605 | F18: 0.02193596
A19: 46357 | B19: 0.02216 | C19: 0.02076 | D19: 0.022837844 | F19: 0.022109386
... A607: 64254 | B607: 0.033886043 | C607: 0.03302814 | D607: 0.033241542 | F607: 0.029414509

Sheet solvencii lab
B2: column_0 | C2: column_1 | D2: column_2 | E2: column_3 | F2: column_4 | G2: column_5 | H2: column_6 | I2: column_7 | J2: column_8 | K2: column_9 | L2: column_10 | M2: column_11 | N2: column_12 | O2: column_13 | P2: column_14 | Q2: column_15 | R2: column_16 | S2: column_17 | T2: column_18 | U2: column_19 | V2: column_20 | W2: column_21 | X2: column_22 | Y2: column_23 | Z2: column_24 | AA2: column_25 | AB2: column_26 | AC2: column_27 | AD2: column_28 | AE2: column_29 | AF2: column_30 | AG2: column_31 | AH2: column_32 | AI2: column_33 | AJ2: column_34 | AK2: column_35 | AL2: column_36 | AM2: column_37 | AN2: column_38 | AO2: column_39 | AP2: column_40 | AQ2: column_41 | AR2: column_42 | AS2: column_43 | AT2: column_44 | AU2: column_45 | AV2: column_46 | AW2: column_47 | AX2: column_48 | AY2: column_49 | AZ2: column_50 | BA2: column_51 | BB2: column_52 | BC2: column_53 | BD2: column_54 | BE2: column_55 | BF2: column_56 | BG2: column_57 | BH2: column_58 | BI2: column_59 | BJ2: column_60 | BK2: column_61 | BL2: column_62 | BM2: column_63 | BN2: column_64 | BO2: column_65 | BP2: column_66 | BQ2: column_67 | BR2: column_68 | BS2: column_69 | BT2: column_70 | BU2: column_71 | BV2: column_72 | BW2: column_73 | BX2: column_74 | BY2: column_75 | BZ2: column_76 | CA2: column_77 | CB2: column_78 | CC2: column_79 | CD2: column_80 | CE2: column_81 | CF2: column_82 | CG2: column_83 | CH2: column_84 | CI2: column_85 | CJ2: column_86 | CK2: column_87 | CL2: column_88 | CM2: column_89 | CN2: column_90 | CO2: column_91 | CP2: column_92 | CQ2: column_93 | CR2: column_94 | CS2: column_95 | CT2: column_96
B3: 0.02016996 | C3: 0.020230743 | D3: 0.02007805 | E3: 0.020687843 | F3: 0.021444527 | G3: 0.022200114 | H3: 0.022956638 | I3: 0.023712065 | J3: 0.024468429 | K3: 0.025223697 | L3: 0.025979901 | M3: 0.026735008 | N3: 0.027491052 | O3: 0.02728294 | P3: 0.027073824 | Q3: 0.026865705 | R3: 0.026657581 | S3: 0.026448453 | T3: 0.026240321 | U3: 0.026032185 | V3: 0.025823044 | W3: 0.0256149 | X3: 0.025406752 | Y3: 0.025197599 | Z3: 0.024989443 | AA3: 0.024565666 | AB3: 0.02414288 | AC3: 0.023719052 | AD3: 0.023295198 | AE3: 0.022872334 | AF3: 0.022448429 | AG3: 0.022024497 | AH3: 0.021601556 | AI3: 0.021177573 | AJ3: 0.020753564 | AK3: 0.020330546 | AL3: 0.019906485 | AM3: 0.019906485 | AN3: 0.019906485 | AO3: 0.019906485 | AP3: 0.019906485 | AQ3: 0.019906485 | AR3: 0.019906485 | AS3: 0.019906485 | AT3: 0.019906485 | AU3: 0.019906485 | AV3: 0.019906485 | AW3: 0.019906485 | AX3: 0.019906485 | AY3: 0.019906485 | AZ3: 0.019906485 | BA3: 0.019906485 | BB3: 0.019906485 | BC3: 0.019906485 | BD3: 0.019906485 | BE3: 0.019906485 | BF3: 0.019906485 | BG3: 0.019906485 | BH3: 0.019906485 | BI3: 0.019906485 | BJ3: 0.019906485 | BK3: 0.019906485 | BL3: 0.019906485 | BM3: 0.019906485 | BN3: 0.019906485 | BO3: 0.019906485 | BP3: 0.019906485 | BQ3: 0.019906485 | BR3: 0.019906485 | BS3: 0.019906485 | BT3: 0.019906485 | BU3: 0.019906485 | BV3: 0.019906485 | BW3: 0.019906485 | BX3: 0.019906485 | BY3: 0.019906485 | BZ3: 0.019906485 | CA3: 0.019906485 | CB3: 0.019906485 | CC3: 0.019906485 | CD3: 0.019906485 | CE3: 0.019906485 | CF3: 0.019906485 | CG3: 0.019906485 | CH3: 0.019906485 | CI3: 0.019906485 | CJ3: 0.019906485 | CK3: 0.019906485 | CL3: 0.019906485 | CM3: 0.019906485 | CN3: 0.019906485 | CO3: 0.019906485 | CP3: 0.019906485 | CQ3: 0.019906485 | CR3: 0.019906485 | CS3: 0.019906485 | CT3: 0.019906485
B4: 0.020205415 | C4: 0.020262135 | D4: 0.020099231 | E4: 0.020727714 | F4: 0.021480204 | G4: 0.022231646 | H4: 0.02298406 | I4: 0.023735426 | J4: 0.024487764 | K4: 0.025239053 | L4: 0.025991315 | M4: 0.026742529 | N4: 0.027494715 | O4: 0.027286669 | P4: 0.027077621 | Q4: 0.026869571 | R4: 0.02666152 | S4: 0.026452467 | T4: 0.026244413 | U4: 0.026036357 | V4: 0.025827299 | W4: 0.025619239 | X4: 0.025411178 | Y4: 0.025202115 | Z4: 0.02499405 | AA4: 0.024572887 | AB4: 0.024152721 | AC4: 0.023731533 | AD4: 0.023310333 | AE4: 0.02289013 | AF4: 0.022468905 | AG4: 0.022047667 | AH4: 0.021627427 | AI4: 0.021206165 | AJ4: 0.02078489 | AK4: 0.020364614 | AL4: 0.019943314 | AM4: 0.019943314 | AN4: 0.019943314 | AO4: 0.019943314 | AP4: 0.019943314 | AQ4: 0.019943314 | AR4: 0.019943314 | AS4: 0.019943314 | AT4: 0.019943314 | AU4: 0.019943314 | AV4: 0.019943314 | AW4: 0.019943314 | AX4: 0.019943314 | AY4: 0.019943314 | AZ4: 0.019943314 | BA4: 0.019943314 | BB4: 0.019943314 | BC4: 0.019943314 | BD4: 0.019943314 | BE4: 0.019943314 | BF4: 0.019943314 | BG4: 0.019943314 | BH4: 0.019943314 | BI4: 0.019943314 | BJ4: 0.019943314 | BK4: 0.019943314 | BL4: 0.019943314 | BM4: 0.019943314 | BN4: 0.019943314 | BO4: 0.019943314 | BP4: 0.019943314 | BQ4: 0.019943314 | BR4: 0.019943314 | BS4: 0.019943314 | BT4: 0.019943314 | BU4: 0.019943314 | BV4: 0.019943314 | BW4: 0.019943314 | BX4: 0.019943314 | BY4: 0.019943314 | BZ4: 0.019943314 | CA4: 0.019943314 | CB4: 0.019943314 | CC4: 0.019943314 | CD4: 0.019943314 | CE4: 0.019943314 | CF4: 0.019943314 | CG4: 0.019943314 | CH4: 0.019943314 | CI4: 0.019943314 | CJ4: 0.019943314 | CK4: 0.019943314 | CL4: 0.019943314 | CM4: 0.019943314 | CN4: 0.019943314 | CO4: 0.019943314 | CP4: 0.019943314 | CQ4: 0.019943314 | CR4: 0.019943314 | CS4: 0.019943314 | CT4: 0.019943314
B5: 0.02026 | C5: 0.02031 | D5: 0.02013 | E5: 0.02079 | F5: 0.021536 | G5: 0.022281 | H5: 0.023027 | I5: 0.023772 | J5: 0.024518 | K5: 0.025263 | L5: 0.026009 | M5: 0.026754 | N5: 0.0275 | O5: 0.027292 | P5: 0.027083 | Q5: 0.026875 | R5: 0.026667 | S5: 0.026458 | T5: 0.02625 | U5: 0.026042 | V5: 0.025833 | W5: 0.025625 | X5: 0.025417 | Y5: 0.025208 | Z5: 0.025 | AA5: 0.024583 | AB5: 0.024167 | AC5: 0.02375 | AD5: 0.023333 | AE5: 0.022917 | AF5: 0.0225 | AG5: 0.022083 | AH5: 0.021667 | AI5: 0.02125 | AJ5: 0.020833 | AK5: 0.020417 | AL5: 0.02 | AM5: 0.02 | AN5: 0.02 | AO5: 0.02 | AP5: 0.02 | AQ5: 0.02 | AR5: 0.02 | AS5: 0.02 | AT5: 0.02 | AU5: 0.02 | AV5: 0.02 | AW5: 0.02 | AX5: 0.02 | AY5: 0.02 | AZ5: 0.02 | BA5: 0.02 | BB5: 0.02 | BC5: 0.02 | BD5: 0.02 | BE5: 0.02 | BF5: 0.02 | BG5: 0.02 | BH5: 0.02 | BI5: 0.02 | BJ5: 0.02 | BK5: 0.02 | BL5: 0.02 | BM5: 0.02 | BN5: 0.02 | BO5: 0.02 | BP5: 0.02 | BQ5: 0.02 | BR5: 0.02 | BS5: 0.02 | BT5: 0.02 | BU5: 0.02 | BV5: 0.02 | BW5: 0.02 | BX5: 0.02 | BY5: 0.02 | BZ5: 0.02 | CA5: 0.02 | CB5: 0.02 | CC5: 0.02 | CD5: 0.02 | CE5: 0.02 | CF5: 0.02 | CG5: 0.02 | CH5: 0.02 | CI5: 0.02 | CJ5: 0.02 | CK5: 0.02 | CL5: 0.02 | CM5: 0.02 | CN5: 0.02 | CO5: 0.02 | CP5: 0.02 | CQ5: 0.02 | CR5: 0.02 | CS5: 0.02 | CT5: 0.02
B6: 0.020331223 | C6: 0.0203722 | D6: 0.020169131 | E6: 0.020871777 | F6: 0.0216093 | G6: 0.022345869 | H6: 0.023083459 | I6: 0.023820096 | J6: 0.024557753 | K6: 0.025294457 | L6: 0.026032183 | M6: 0.026768955 | N6: 0.027506748 | O6: 0.027298777 | P6: 0.027089807 | Q6: 0.026881838 | R6: 0.026673871 | S6: 0.026464904 | T6: 0.026256938 | U6: 0.026048974 | V6: 0.02584001 | W6: 0.025632048 | X6: 0.025424086 | Y6: 0.025215126 | Z6: 0.025007167 | AA6: 0.024595675 | AB6: 0.024185182 | AC6: 0.023773713 | AD6: 0.023362256 | AE6: 0.022951796 | AF6: 0.02254036 | AG6: 0.022128936 | AH6: 0.021718509 | AI6: 0.021307107 | AJ6: 0.020895716 | AK6: 0.020485322 | AL6: 0.020073953 | AM6: 0.020073953 | AN6: 0.020073953 | AO6: 0.020073953 | AP6: 0.020073953 | AQ6: 0.020073953 | AR6: 0.020073953 | AS6: 0.020073953 | AT6: 0.020073953 | AU6: 0.020073953 | AV6: 0.020073953 | AW6: 0.020073953 | AX6: 0.020073953 | AY6: 0.020073953 | AZ6: 0.020073953 | BA6: 0.020073953 | BB6: 0.020073953 | BC6: 0.020073953 | BD6: 0.020073953 | BE6: 0.020073953 | BF6: 0.020073953 | BG6: 0.020073953 | BH6: 0.020073953 | BI6: 0.020073953 | BJ6: 0.020073953 | BK6: 0.020073953 | BL6: 0.020073953 | BM6: 0.020073953 | BN6: 0.020073953 | BO6: 0.020073953 | BP6: 0.020073953 | BQ6: 0.020073953 | BR6: 0.020073953 | BS6: 0.020073953 | BT6: 0.020073953 | BU6: 0.020073953 | BV6: 0.020073953 | BW6: 0.020073953 | BX6: 0.020073953 | BY6: 0.020073953 | BZ6: 0.020073953 | CA6: 0.020073953 | CB6: 0.020073953 | CC6: 0.020073953 | CD6: 0.020073953 | CE6: 0.020073953 | CF6: 0.020073953 | CG6: 0.020073953 | CH6: 0.020073953 | CI6: 0.020073953 | CJ6: 0.020073953 | CK6: 0.020073953 | CL6: 0.020073953 | CM6: 0.020073953 | CN6: 0.020073953 | CO6: 0.020073953 | CP6: 0.020073953 | CQ6: 0.020073953 | CR6: 0.020073953 | CS6: 0.020073953 | CT6: 0.020073953
B7: 0.02041076 | C7: 0.020441589 | D7: 0.020212533 | E7: 0.020963266 | F7: 0.021691346 | G7: 0.022418519 | H7: 0.023146728 | I7: 0.02387403 | J7: 0.024602367 | K7: 0.025329797 | L7: 0.026058264 | M7: 0.026785822 | N7: 0.027514418 | O7: 0.027306468 | P7: 0.02709752 | Q7: 0.026889573 | R7: 0.026681628 | S7: 0.026472685 | T7: 0.026264744 | U7: 0.026056804 | V7: 0.025847866 | W7: 0.02563993 | X7: 0.025431995 | Y7: 0.025223063 | Z7: 0.025015132 | AA7: 0.024609808 | AB7: 0.024205477 | AC7: 0.023800195 | AD7: 0.023394934 | AE7: 0.022990666 | AF7: 0.022585448 | AG7: 0.02218025 | AH7: 0.021776046 | AI7: 0.021370891 | AJ7: 0.020965757 | AK7: 0.020561616 | AL7: 0.020156524 | AM7: 0.020156524 | AN7: 0.020156524 | AO7: 0.020156524 | AP7: 0.020156524 | AQ7: 0.020156524 | AR7: 0.020156524 | AS7: 0.020156524 | AT7: 0.020156524 | AU7: 0.020156524 | AV7: 0.020156524 | AW7: 0.020156524 | AX7: 0.020156524 | AY7: 0.020156524 | AZ7: 0.020156524 | BA7: 0.020156524 | BB7: 0.020156524 | BC7: 0.020156524 | BD7: 0.020156524 | BE7: 0.020156524 | BF7: 0.020156524 | BG7: 0.020156524 | BH7: 0.020156524 | BI7: 0.020156524 | BJ7: 0.020156524 | BK7: 0.020156524 | BL7: 0.020156524 | BM7: 0.020156524 | BN7: 0.020156524 | BO7: 0.020156524 | BP7: 0.020156524 | BQ7: 0.020156524 | BR7: 0.020156524 | BS7: 0.020156524 | BT7: 0.020156524 | BU7: 0.020156524 | BV7: 0.020156524 | BW7: 0.020156524 | BX7: 0.020156524 | BY7: 0.020156524 | BZ7: 0.020156524 | CA7: 0.020156524 | CB7: 0.020156524 | CC7: 0.020156524 | CD7: 0.020156524 | CE7: 0.020156524 | CF7: 0.020156524 | CG7: 0.020156524 | CH7: 0.020156524 | CI7: 0.020156524 | CJ7: 0.020156524 | CK7: 0.020156524 | CL7: 0.020156524 | CM7: 0.020156524 | CN7: 0.020156524 | CO7: 0.020156524 | CP7: 0.020156524 | CQ7: 0.020156524 | CR7: 0.020156524 | CS7: 0.020156524 | CT7: 0.020156524
B8: 0.02049421 | C8: 0.020514391 | D8: 0.020258046 | E8: 0.021059298 | F8: 0.021777512 | G8: 0.022494863 | H8: 0.023213262 | I8: 0.023930797 | J8: 0.02464938 | K8: 0.0253671 | L8: 0.026085868 | M8: 0.026803772 | N8: 0.027522725 | O8: 0.027314792 | P8: 0.027105861 | Q8: 0.026897932 | R8: 0.026690006 | S8: 0.026481081 | T8: 0.026273159 | U8: 0.026065239 | V8: 0.025856322 | W8: 0.025648407 | X8: 0.025440494 | Y8: 0.025231584 | Z8: 0.025023675 | AA8: 0.024624812 | AB8: 0.024226936 | AC8: 0.023828133 | AD8: 0.023429361 | AE8: 0.023031575 | AF8: 0.022632864 | AG8: 0.022234183 | AH8: 0.021836488 | AI8: 0.021437867 | AJ8: 0.021039277 | AK8: 0.020641673 | AL8: 0.020243143 | AM8: 0.020243143 | AN8: 0.020243143 | AO8: 0.020243143 | AP8: 0.020243143 | AQ8: 0.020243143 | AR8: 0.020243143 | AS8: 0.020243143 | AT8: 0.020243143 | AU8: 0.020243143 | AV8: 0.020243143 | AW8: 0.020243143 | AX8: 0.020243143 | AY8: 0.020243143 | AZ8: 0.020243143 | BA8: 0.020243143 | BB8: 0.020243143 | BC8: 0.020243143 | BD8: 0.020243143 | BE8: 0.020243143 | BF8: 0.020243143 | BG8: 0.020243143 | BH8: 0.020243143 | BI8: 0.020243143 | BJ8: 0.020243143 | BK8: 0.020243143 | BL8: 0.020243143 | BM8: 0.020243143 | BN8: 0.020243143 | BO8: 0.020243143 | BP8: 0.020243143 | BQ8: 0.020243143 | BR8: 0.020243143 | BS8: 0.020243143 | BT8: 0.020243143 | BU8: 0.020243143 | BV8: 0.020243143 | BW8: 0.020243143 | BX8: 0.020243143 | BY8: 0.020243143 | BZ8: 0.020243143 | CA8: 0.020243143 | CB8: 0.020243143 | CC8: 0.020243143 | CD8: 0.020243143 | CE8: 0.020243143 | CF8: 0.020243143 | CG8: 0.020243143 | CH8: 0.020243143 | CI8: 0.020243143 | CJ8: 0.020243143 | CK8: 0.020243143 | CL8: 0.020243143 | CM8: 0.020243143 | CN8: 0.020243143 | CO8: 0.020243143 | CP8: 0.020243143 | CQ8: 0.020243143 | CR8: 0.020243143 | CS8: 0.020243143 | CT8: 0.020243143
B9: 0.020579691 | C9: 0.020588989 | D9: 0.020304744 | E9: 0.02115766 | F9: 0.021865817 | G9: 0.022573151 | H9: 0.023281542 | I9: 0.023989112 | J9: 0.024697739 | K9: 0.025405543 | L9: 0.026114407 | M9: 0.026822447 | N9: 0.027531547 | O9: 0.027323628 | P9: 0.027114713 | Q9: 0.026906799 | R9: 0.026698888 | S9: 0.026489981 | T9: 0.026282075 | U9: 0.026074172 | V9: 0.025865273 | W9: 0.025657376 | X9: 0.025449481 | Y9: 0.02524059 | Z9: 0.025032701 | AA9: 0.024640438 | AB9: 0.024249153 | AC9: 0.023856967 | AD9: 0.02346482 | AE9: 0.023073652 | AF9: 0.022681581 | AG9: 0.02228955 | AH9: 0.021898498 | AI9: 0.021506543 | AJ9: 0.021114628 | AK9: 0.020723691 | AL9: 0.020331853 | AM9: 0.020331853 | AN9: 0.020331853 | AO9: 0.020331853 | AP9: 0.020331853 | AQ9: 0.020331853 | AR9: 0.020331853 | AS9: 0.020331853 | AT9: 0.020331853 | AU9: 0.020331853 | AV9: 0.020331853 | AW9: 0.020331853 | AX9: 0.020331853 | AY9: 0.020331853 | AZ9: 0.020331853 | BA9: 0.020331853 | BB9: 0.020331853 | BC9: 0.020331853 | BD9: 0.020331853 | BE9: 0.020331853 | BF9: 0.020331853 | BG9: 0.020331853 | BH9: 0.020331853 | BI9: 0.020331853 | BJ9: 0.020331853 | BK9: 0.020331853 | BL9: 0.020331853 | BM9: 0.020331853 | BN9: 0.020331853 | BO9: 0.020331853 | BP9: 0.020331853 | BQ9: 0.020331853 | BR9: 0.020331853 | BS9: 0.020331853 | BT9: 0.020331853 | BU9: 0.020331853 | BV9: 0.020331853 | BW9: 0.020331853 | BX9: 0.020331853 | BY9: 0.020331853 | BZ9: 0.020331853 | CA9: 0.020331853 | CB9: 0.020331853 | CC9: 0.020331853 | CD9: 0.020331853 | CE9: 0.020331853 | CF9: 0.020331853 | CG9: 0.020331853 | CH9: 0.020331853 | CI9: 0.020331853 | CJ9: 0.020331853 | CK9: 0.020331853 | CL9: 0.020331853 | CM9: 0.020331853 | CN9: 0.020331853 | CO9: 0.020331853 | CP9: 0.020331853 | CQ9: 0.020331853 | CR9: 0.020331853 | CS9: 0.020331853 | CT9: 0.020331853
B10: 0.020666264 | C10: 0.020664577 | D10: 0.020352164 | E10: 0.02125725 | F10: 0.021955271 | G10: 0.022652509 | H10: 0.023350812 | I10: 0.024048331 | J10: 0.024746916 | K10: 0.025444718 | L10: 0.026143586 | M10: 0.026841671 | N10: 0.027540822 | O10: 0.027332917 | P10: 0.027124015 | Q10: 0.026916115 | R10: 0.026708219 | S10: 0.026499326 | T10: 0.026291436 | U10: 0.026083549 | V10: 0.025874665 | W10: 0.025666784 | X10: 0.025458907 | Y10: 0.025250033 | Z10: 0.025042161 | AA10: 0.024656558 | AB10: 0.024271927 | AC10: 0.023886416 | AD10: 0.023500952 | AE10: 0.023116459 | AF10: 0.022731088 | AG10: 0.022345763 | AH10: 0.021961408 | AI10: 0.021576175 | AJ10: 0.021190989 | AK10: 0.020806772 | AL10: 0.020421678 | AM10: 0.020421678 | AN10: 0.020421678 | AO10: 0.020421678 | AP10: 0.020421678 | AQ10: 0.020421678 | AR10: 0.020421678 | AS10: 0.020421678 | AT10: 0.020421678 | AU10: 0.020421678 | AV10: 0.020421678 | AW10: 0.020421678 | AX10: 0.020421678 | AY10: 0.020421678 | AZ10: 0.020421678 | BA10: 0.020421678 | BB10: 0.020421678 | BC10: 0.020421678 | BD10: 0.020421678 | BE10: 0.020421678 | BF10: 0.020421678 | BG10: 0.020421678 | BH10: 0.020421678 | BI10: 0.020421678 | BJ10: 0.020421678 | BK10: 0.020421678 | BL10: 0.020421678 | BM10: 0.020421678 | BN10: 0.020421678 | BO10: 0.020421678 | BP10: 0.020421678 | BQ10: 0.020421678 | BR10: 0.020421678 | BS10: 0.020421678 | BT10: 0.020421678 | BU10: 0.020421678 | BV10: 0.020421678 | BW10: 0.020421678 | BX10: 0.020421678 | BY10: 0.020421678 | BZ10: 0.020421678 | CA10: 0.020421678 | CB10: 0.020421678 | CC10: 0.020421678 | CD10: 0.020421678 | CE10: 0.020421678 | CF10: 0.020421678 | CG10: 0.020421678 | CH10: 0.020421678 | CI10: 0.020421678 | CJ10: 0.020421678 | CK10: 0.020421678 | CL10: 0.020421678 | CM10: 0.020421678 | CN10: 0.020421678 | CO10: 0.020421678 | CP10: 0.020421678 | CQ10: 0.020421678 | CR10: 0.020421678 | CS10: 0.020421678 | CT10: 0.020421678
B11: 0.020753409 | C11: 0.020740708 | D11: 0.02040005 | E11: 0.021357458 | F11: 0.022045329 | G11: 0.022732455 | H11: 0.02342065 | I11: 0.0241081 | J11: 0.024796621 | K11: 0.025484395 | L11: 0.026173242 | M11: 0.026861343 | N11: 0.027550516 | O11: 0.027342623 | P11: 0.027133734 | Q11: 0.026925848 | R11: 0.026717965 | S11: 0.026509087 | T11: 0.026301211 | U11: 0.026093338 | V11: 0.02588447 | W11: 0.025676604 | X11: 0.025468742 | Y11: 0.025259885 | Z11: 0.02505203 | AA11: 0.024673105 | AB11: 0.024295143 | AC11: 0.023916325 | AD11: 0.02353756 | AE11: 0.023159757 | AF11: 0.022781098 | AG11: 0.022402493 | AH11: 0.022024849 | AI11: 0.02164635 | AJ11: 0.021267904 | AK11: 0.020890419 | AL11: 0.020512078 | AM11: 0.020512078 | AN11: 0.020512078 | AO11: 0.020512078 | AP11: 0.020512078 | AQ11: 0.020512078 | AR11: 0.020512078 | AS11: 0.020512078 | AT11: 0.020512078 | AU11: 0.020512078 | AV11: 0.020512078 | AW11: 0.020512078 | AX11: 0.020512078 | AY11: 0.020512078 | AZ11: 0.020512078 | BA11: 0.020512078 | BB11: 0.020512078 | BC11: 0.020512078 | BD11: 0.020512078 | BE11: 0.020512078 | BF11: 0.020512078 | BG11: 0.020512078 | BH11: 0.020512078 | BI11: 0.020512078 | BJ11: 0.020512078 | BK11: 0.020512078 | BL11: 0.020512078 | BM11: 0.020512078 | BN11: 0.020512078 | BO11: 0.020512078 | BP11: 0.020512078 | BQ11: 0.020512078 | BR11: 0.020512078 | BS11: 0.020512078 | BT11: 0.020512078 | BU11: 0.020512078 | BV11: 0.020512078 | BW11: 0.020512078 | BX11: 0.020512078 | BY11: 0.020512078 | BZ11: 0.020512078 | CA11: 0.020512078 | CB11: 0.020512078 | CC11: 0.020512078 | CD11: 0.020512078 | CE11: 0.020512078 | CF11: 0.020512078 | CG11: 0.020512078 | CH11: 0.020512078 | CI11: 0.020512078 | CJ11: 0.020512078 | CK11: 0.020512078 | CL11: 0.020512078 | CM11: 0.020512078 | CN11: 0.020512078 | CO11: 0.020512078 | CP11: 0.020512078 | CQ11: 0.020512078 | CR11: 0.020512078 | CS11: 0.020512078 | CT11: 0.020512078
B12: 0.020840815 | C12: 0.020817117 | D12: 0.020448249 | E12: 0.02145792 | F12: 0.022135665 | G12: 0.0228127 | H12: 0.023490808 | I12: 0.024168205 | J12: 0.024846678 | K12: 0.02552444 | L12: 0.026203278 | M12: 0.026881405 | N12: 0.027560609 | O12: 0.027352728 | P12: 0.027143851 | Q12: 0.026935978 | R12: 0.026728108 | S12: 0.026519243 | T12: 0.026311381 | U12: 0.026103523 | V12: 0.025894669 | W12: 0.025686818 | X12: 0.025478971 | Y12: 0.025270129 | Z12: 0.025062289 | AA12: 0.024690036 | AB12: 0.024318734 | AC12: 0.023946599 | AD12: 0.023574524 | AE12: 0.0232034 | AF12: 0.022831444 | AG12: 0.022459547 | AH12: 0.022088601 | AI12: 0.021716822 | AJ12: 0.021345103 | AK12: 0.020974334 | AL12: 0.020602733 | AM12: 0.020602733 | AN12: 0.020602733 | AO12: 0.020602733 | AP12: 0.020602733 | AQ12: 0.020602733 | AR12: 0.020602733 | AS12: 0.020602733 | AT12: 0.020602733 | AU12: 0.020602733 | AV12: 0.020602733 | AW12: 0.020602733 | AX12: 0.020602733 | AY12: 0.020602733 | AZ12: 0.020602733 | BA12: 0.020602733 | BB12: 0.020602733 | BC12: 0.020602733 | BD12: 0.020602733 | BE12: 0.020602733 | BF12: 0.020602733 | BG12: 0.020602733 | BH12: 0.020602733 | BI12: 0.020602733 | BJ12: 0.020602733 | BK12: 0.020602733 | BL12: 0.020602733 | BM12: 0.020602733 | BN12: 0.020602733 | BO12: 0.020602733 | BP12: 0.020602733 | BQ12: 0.020602733 | BR12: 0.020602733 | BS12: 0.020602733 | BT12: 0.020602733 | BU12: 0.020602733 | BV12: 0.020602733 | BW12: 0.020602733 | BX12: 0.020602733 | BY12: 0.020602733 | BZ12: 0.020602733 | CA12: 0.020602733 | CB12: 0.020602733 | CC12: 0.020602733 | CD12: 0.020602733 | CE12: 0.020602733 | CF12: 0.020602733 | CG12: 0.020602733 | CH12: 0.020602733 | CI12: 0.020602733 | CJ12: 0.020602733 | CK12: 0.020602733 | CL12: 0.020602733 | CM12: 0.020602733 | CN12: 0.020602733 | CO12: 0.020602733 | CP12: 0.020602733 | CQ12: 0.020602733 | CR12: 0.020602733 | CS12: 0.020602733 | CT12: 0.020602733
B13: 0.020928289 | C13: 0.020893635 | D13: 0.020496665 | E13: 0.021558406 | F13: 0.022226072 | G13: 0.022893061 | H13: 0.023561126 | I13: 0.024228513 | J13: 0.024896978 | K13: 0.025564765 | L13: 0.02623363 | M13: 0.026901819 | N13: 0.027571086 | O13: 0.027363217 | P13: 0.027154353 | Q13: 0.026946492 | R13: 0.026738636 | S13: 0.026529784 | T13: 0.026321935 | U13: 0.02611409 | V13: 0.02590525 | W13: 0.025697414 | X13: 0.025489582 | Y13: 0.025280754 | Z13: 0.02507293 | AA13: 0.024707323 | AB13: 0.024342658 | AC13: 0.023977181 | AD13: 0.023611769 | AE13: 0.023247298 | AF13: 0.022882016 | AG13: 0.0225168 | AH13: 0.022152523 | AI13: 0.021787436 | AJ13: 0.021422414 | AK13: 0.021058331 | AL13: 0.020693438 | AM13: 0.020693438 | AN13: 0.020693438 | AO13: 0.020693438 | AP13: 0.020693438 | AQ13: 0.020693438 | AR13: 0.020693438 | AS13: 0.020693438 | AT13: 0.020693438 | AU13: 0.020693438 | AV13: 0.020693438 | AW13: 0.020693438 | AX13: 0.020693438 | AY13: 0.020693438 | AZ13: 0.020693438 | BA13: 0.020693438 | BB13: 0.020693438 | BC13: 0.020693438 | BD13: 0.020693438 | BE13: 0.020693438 | BF13: 0.020693438 | BG13: 0.020693438 | BH13: 0.020693438 | BI13: 0.020693438 | BJ13: 0.020693438 | BK13: 0.020693438 | BL13: 0.020693438 | BM13: 0.020693438 | BN13: 0.020693438 | BO13: 0.020693438 | BP13: 0.020693438 | BQ13: 0.020693438 | BR13: 0.020693438 | BS13: 0.020693438 | BT13: 0.020693438 | BU13: 0.020693438 | BV13: 0.020693438 | BW13: 0.020693438 | BX13: 0.020693438 | BY13: 0.020693438 | BZ13: 0.020693438 | CA13: 0.020693438 | CB13: 0.020693438 | CC13: 0.020693438 | CD13: 0.020693438 | CE13: 0.020693438 | CF13: 0.020693438 | CG13: 0.020693438 | CH13: 0.020693438 | CI13: 0.020693438 | CJ13: 0.020693438 | CK13: 0.020693438 | CL13: 0.020693438 | CM13: 0.020693438 | CN13: 0.020693438 | CO13: 0.020693438 | CP13: 0.020693438 | CQ13: 0.020693438 | CR13: 0.020693438 | CS13: 0.020693438 | CT13: 0.020693438
B14: 0.021015699 | C14: 0.020970151 | D14: 0.020545233 | E14: 0.021658766 | F14: 0.022316415 | G14: 0.02297342 | H14: 0.0236315 | I14: 0.024288935 | J14: 0.024947447 | K14: 0.025605314 | L14: 0.026264259 | M14: 0.02692256 | N14: 0.027581939 | O14: 0.027374082 | P14: 0.027165231 | Q14: 0.026957382 | R14: 0.026749538 | S14: 0.026540699 | T14: 0.026332864 | U14: 0.026125033 | V14: 0.025916207 | W14: 0.025708384 | X14: 0.025500566 | Y14: 0.025291754 | Z14: 0.025083945 | AA14: 0.024724949 | AB14: 0.024366885 | AC14: 0.02400803 | AD14: 0.023649245 | AE14: 0.02329139 | AF14: 0.022932745 | AG14: 0.02257417 | AH14: 0.022216524 | AI14: 0.021858089 | AJ14: 0.021499723 | AK14: 0.021142287 | AL14: 0.02078406 | AM14: 0.02078406 | AN14: 0.02078406 | AO14: 0.02078406 | AP14: 0.02078406 | AQ14: 0.02078406 | AR14: 0.02078406 | AS14: 0.02078406 | AT14: 0.02078406 | AU14: 0.02078406 | AV14: 0.02078406 | AW14: 0.02078406 | AX14: 0.02078406 | AY14: 0.02078406 | AZ14: 0.02078406 | BA14: 0.02078406 | BB14: 0.02078406 | BC14: 0.02078406 | BD14: 0.02078406 | BE14: 0.02078406 | BF14: 0.02078406 | BG14: 0.02078406 | BH14: 0.02078406 | BI14: 0.02078406 | BJ14: 0.02078406 | BK14: 0.02078406 | BL14: 0.02078406 | BM14: 0.02078406 | BN14: 0.02078406 | BO14: 0.02078406 | BP14: 0.02078406 | BQ14: 0.02078406 | BR14: 0.02078406 | BS14: 0.02078406 | BT14: 0.02078406 | BU14: 0.02078406 | BV14: 0.02078406 | BW14: 0.02078406 | BX14: 0.02078406 | BY14: 0.02078406 | BZ14: 0.02078406 | CA14: 0.02078406 | CB14: 0.02078406 | CC14: 0.02078406 | CD14: 0.02078406 | CE14: 0.02078406 | CF14: 0.02078406 | CG14: 0.02078406 | CH14: 0.02078406 | CI14: 0.02078406 | CJ14: 0.02078406 | CK14: 0.02078406 | CL14: 0.02078406 | CM14: 0.02078406 | CN14: 0.02078406 | CO14: 0.02078406 | CP14: 0.02078406 | CQ14: 0.02078406 | CR14: 0.02078406 | CS14: 0.02078406 | CT14: 0.02078406
... B602: 0.033767266 | C602: 0.033414934 | D602: 0.032344849 | E602: 0.034528883 | F602: 0.034606117 | G602: 0.034683464 | H602: 0.034760951 | I602: 0.034838553 | J602: 0.034916298 | K602: 0.03499416 | L602: 0.035072167 | M602: 0.035150292 | N602: 0.035228565 | O602: 0.035108464 | P602: 0.034987973 | Q602: 0.034868241 | R602: 0.034748693 | S602: 0.034628752 | T602: 0.034509565 | U602: 0.034390558 | V602: 0.034271158 | W602: 0.034152506 | X602: 0.034034031 | Y602: 0.033915162 | Z602: 0.033797036 | AA602: 0.033791498 | AB602: 0.033785973 | AC602: 0.033780436 | AD602: 0.0337749 | AE602: 0.033769378 | AF602: 0.033763843 | AG602: 0.033758308 | AH602: 0.033752788 | AI602: 0.033747255 | AJ602: 0.033741722 | AK602: 0.033736203 | AL602: 0.033730672 | AM602: 0.033730672 | AN602: 0.033730672 | AO602: 0.033730672 | AP602: 0.033730672 | AQ602: 0.033730672 | AR602: 0.033730672 | AS602: 0.033730672 | AT602: 0.033730672 | AU602: 0.033730672 | AV602: 0.033730672 | AW602: 0.033730672 | AX602: 0.033730672 | AY602: 0.033730672 | AZ602: 0.033730672 | BA602: 0.033730672 | BB602: 0.033730672 | BC602: 0.033730672 | BD602: 0.033730672 | BE602: 0.033730672 | BF602: 0.033730672 | BG602: 0.033730672 | BH602: 0.033730672 | BI602: 0.033730672 | BJ602: 0.033730672 | BK602: 0.033730672 | BL602: 0.033730672 | BM602: 0.033730672 | BN602: 0.033730672 | BO602: 0.033730672 | BP602: 0.033730672 | BQ602: 0.033730672 | BR602: 0.033730672 | BS602: 0.033730672 | BT602: 0.033730672 | BU602: 0.033730672 | BV602: 0.033730672 | BW602: 0.033730672 | BX602: 0.033730672 | BY602: 0.033730672 | BZ602: 0.033730672 | CA602: 0.033730672 | CB602: 0.033730672 | CC602: 0.033730672 | CD602: 0.033730672 | CE602: 0.033730672 | CF602: 0.033730672 | CG602: 0.033730672 | CH602: 0.033730672 | CI602: 0.033730672 | CJ602: 0.033730672 | CK602: 0.033730672 | CL602: 0.033730672 | CM602: 0.033730672 | CN602: 0.033730672 | CO602: 0.033730672 | CP602: 0.033730672 | CQ602: 0.033730672 | CR602: 0.033730672 | CS602: 0.033730672 | CT602: 0.033730672
